Workbook
Name SegmentaciónDeDatos_Cliente: #N/A
Name SegmentaciónDeDatos_Estado: #N/A
Name SegmentaciónDeDatos_Mes_de_facturación: #N/A
Name SegmentaciónDeDatos_Mes_facturado: #N/A

Sheet Consolidado
A1: N° pedido de compra | B1: Sec. Factura | C1: Mes de facturación | D1: Cliente | E1: Descripción | F1: Tipo de moneda | G1: Monto facturado | H1: Estado | I1: Fecha de envío | J1: TRM DIAN | K1: Monto COP reportado DIAN | L1: Monto COP esperado
H2: =IFERROR(IF(AND(COUNTIF(RegistroPago!$A$1:$A$2000,Consolidado!B2)>0,INDEX(RegistroPago!$E$1:$E$2000,MATCH(Consolidado!B2,RegistroPago!$A$1:$A$2000,0))<>""),"PAGADA",IF(I2<>"","PENDIENTE","SIN EMITIR")),"") | K2: =IF(J2<>"",J2*G2,"") | L2: =IF(K2<>"",K2*87.5%,"")
H3: =IFERROR(IF(AND(COUNTIF(RegistroPago!$A$1:$A$2000,Consolidado!B3)>0,INDEX(RegistroPago!$E$1:$E$2000,MATCH(Consolidado!B3,RegistroPago!$A$1:$A$2000,0))<>""),"PAGADA",IF(I3<>"","PENDIENTE","SIN EMITIR")),"") | K3: =IF(J3<>"",J3*G3,"") | L3: =IF(K3<>"",K3*87.5%,"")
H4: =IFERROR(IF(AND(COUNTIF(RegistroPago!$A$1:$A$2000,Consolidado!B4)>0,INDEX(RegistroPago!$E$1:$E$2000,MATCH(Consolidado!B4,RegistroPago!$A$1:$A$2000,0))<>""),"PAGADA",IF(I4<>"","PENDIENTE","SIN EMITIR")),"") | K4: =IF(J4<>"",J4*G4,"") | L4: =IF(K4<>"",K4*87.5%,"")
H5: =IFERROR(IF(AND(COUNTIF(RegistroPago!$A$1:$A$2000,Consolidado!B5)>0,INDEX(RegistroPago!$E$1:$E$2000,MATCH(Consolidado!B5,RegistroPago!$A$1:$A$2000,0))<>""),"PAGADA",IF(I5<>"","PENDIENTE","SIN EMITIR")),"") | K5: =IF(J5<>"",J5*G5,"") | L5: =IF(K5<>"",K5*87.5%,"")
H6: =IFERROR(IF(AND(COUNTIF(RegistroPago!$A$1:$A$2000,Consolidado!B6)>0,INDEX(RegistroPago!$E$1:$E$2000,MATCH(Consolidado!B6,RegistroPago!$A$1:$A$2000,0))<>""),"PAGADA",IF(I6<>"","PENDIENTE","SIN EMITIR")),"") | K6: =IF(J6<>"",J6*G6,"") | L6: =IF(K6<>"",K6*87.5%,"")
H7: =IFERROR(IF(AND(COUNTIF(RegistroPago!$A$1:$A$2000,Consolidado!B7)>0,INDEX(RegistroPago!$E$1:$E$2000,MATCH(Consolidado!B7,RegistroPago!$A$1:$A$2000,0))<>""),"PAGADA",IF(I7<>"","PENDIENTE","SIN EMITIR")),"") | K7: =IF(J7<>"",J7*G7,"") | L7: =IF(K7<>"",K7*87.5%,"")
H8: =IFERROR(IF(AND(COUNTIF(RegistroPago!$A$1:$A$2000,Consolidado!B8)>0,INDEX(RegistroPago!$E$1:$E$2000,MATCH(Consolidado!B8,RegistroPago!$A$1:$A$2000,0))<>""),"PAGADA",IF(I8<>"","PENDIENTE","SIN EMITIR")),"") | K8: =IF(J8<>"",J8*G8,"") | L8: =IF(K8<>"",K8*87.5%,"")
H9: =IFERROR(IF(AND(COUNTIF(RegistroPago!$A$1:$A$2000,Consolidado!B9)>0,INDEX(RegistroPago!$E$1:$E$2000,MATCH(Consolidado!B9,RegistroPago!$A$1:$A$2000,0))<>""),"PAGADA",IF(I9<>"","PENDIENTE","SIN EMITIR")),"") | K9: =IF(J9<>"",J9*G9,"") | L9: =IF(K9<>"",K9*87.5%,"")
H10: =IFERROR(IF(AND(COUNTIF(RegistroPago!$A$1:$A$2000,Consolidado!B10)>0,INDEX(RegistroPago!$E$1:$E$2000,MATCH(Consolidado!B10,RegistroPago!$A$1:$A$2000,0))<>""),"PAGADA",IF(I10<>"","PENDIENTE","SIN EMITIR")),"") | K10: =IF(J10<>"",J10*G10,"") | L10: =IF(K10<>"",K10*87.5%,"")
H11: =IFERROR(IF(AND(COUNTIF(RegistroPago!$A$1:$A$2000,Consolidado!B11)>0,INDEX(RegistroPago!$E$1:$E$2000,MATCH(Consolidado!B11,RegistroPago!$A$1:$A$2000,0))<>""),"PAGADA",IF(I11<>"","PENDIENTE","SIN EMITIR")),"") | K11: =IF(J11<>"",J11*G11,"") | L11: =IF(K11<>"",K11*87.5%,"")
H12: =IFERROR(IF(AND(COUNTIF(RegistroPago!$A$1:$A$2000,Consolidado!B12)>0,INDEX(RegistroPago!$E$1:$E$2000,MATCH(Consolidado!B12,RegistroPago!$A$1:$A$2000,0))<>""),"PAGADA",IF(I12<>"","PENDIENTE","SIN EMITIR")),"") | K12: =IF(J12<>"",J12*G12,"") | L12: =IF(K12<>"",K12*87.5%,"")
H13: =IFERROR(IF(AND(COUNTIF(RegistroPago!$A$1:$A$2000,Consolidado!B13)>0,INDEX(RegistroPago!$E$1:$E$2000,MATCH(Consolidado!B13,RegistroPago!$A$1:$A$2000,0))<>""),"PAGADA",IF(I13<>"","PENDIENTE","SIN EMITIR")),"") | K13: =IF(J13<>"",J13*G13,"") | L13: =IF(K13<>"",K13*87.5%,"")
... H47: =IFERROR(IF(AND(COUNTIF(RegistroPago!$A$1:$A$2000,Consolidado!B47)>0,INDEX(RegistroPago!$E$1:$E$2000,MATCH(Consolidado!B47,RegistroPago!$A$1:$A$2000,0))<>""),"PAGADA",IF(I47<>"","PENDIENTE","SIN EMITIR")),"") | K47: =IF(J47<>"",J47*G47,"") | L47: =IF(K47<>"",K47*87.5%,"")
H48: ANULADA | K48: =IF(J48<>"",J48*G48,"") | L48: =IF(K48<>"",K48*87.5%,"")
H49: =IFERROR(IF(AND(COUNTIF(RegistroPago!$A$1:$A$2000,Consolidado!B49)>0,INDEX(RegistroPago!$E$1:$E$2000,MATCH(Consolidado!B49,RegistroPago!$A$1:$A$2000,0))<>""),"PAGADA",IF(I49<>"","PENDIENTE","SIN EMITIR")),"") | K49: =IF(J49<>"",J49*G49,"") | L49: =IF(K49<>"",K49*87.5%,"")
H50: =IFERROR(IF(AND(COUNTIF(RegistroPago!$A$1:$A$2000,Consolidado!B50)>0,INDEX(RegistroPago!$E$1:$E$2000,MATCH(Consolidado!B50,RegistroPago!$A$1:$A$2000,0))<>""),"PAGADA",IF(I50<>"","PENDIENTE","SIN EMITIR")),"") | K50: =IF(J50<>"",J50*G50,"") | L50: =IF(K50<>"",K50*87.5%,"")
H51: =IFERROR(IF(AND(COUNTIF(RegistroPago!$A$1:$A$2000,Consolidado!B51)>0,INDEX(RegistroPago!$E$1:$E$2000,MATCH(Consolidado!B51,RegistroPago!$A$1:$A$2000,0))<>""),"PAGADA",IF(I51<>"","PENDIENTE","SIN EMITIR")),"") | K51: =IF(J51<>"",J51*G51,"") | L51: =IF(K51<>"",K51*87.5%,"")
H52: =IFERROR(IF(AND(COUNTIF(RegistroPago!$A$1:$A$2000,Consolidado!B52)>0,INDEX(RegistroPago!$E$1:$E$2000,MATCH(Consolidado!B52,RegistroPago!$A$1:$A$2000,0))<>""),"PAGADA",IF(I52<>"","PENDIENTE","SIN EMITIR")),"") | K52: =IF(J52<>"",J52*G52,"") | L52: =IF(K52<>"",K52*87.5%,"")
H53: =IFERROR(IF(AND(COUNTIF(RegistroPago!$A$1:$A$2000,Consolidado!B53)>0,INDEX(RegistroPago!$E$1:$E$2000,MATCH(Consolidado!B53,RegistroPago!$A$1:$A$2000,0))<>""),"PAGADA",IF(I53<>"","PENDIENTE","SIN EMITIR")),"") | K53: =IF(J53<>"",J53*G53,"") | L53: =IF(K53<>"",K53*87.5%,"")
H54: =IFERROR(IF(AND(COUNTIF(RegistroPago!$A$1:$A$2000,Consolidado!B54)>0,INDEX(RegistroPago!$E$1:$E$2000,MATCH(Consolidado!B54,RegistroPago!$A$1:$A$2000,0))<>""),"PAGADA",IF(I54<>"","PENDIENTE","SIN EMITIR")),"") | K54: =IF(J54<>"",J54*G54,"") | L54: =IF(K54<>"",K54*87.5%,"")
H55: =IFERROR(IF(AND(COUNTIF(RegistroPago!$A$1:$A$2000,Consolidado!B55)>0,INDEX(RegistroPago!$E$1:$E$2000,MATCH(Consolidado!B55,RegistroPago!$A$1:$A$2000,0))<>""),"PAGADA",IF(I55<>"","PENDIENTE","SIN EMITIR")),"") | K55: =IF(J55<>"",J55*G55,"") | L55: =IF(K55<>"",K55*87.5%,"")
H56: DUPLICADA | K56: =IF(J56<>"",J56*G56,"") | L56: =IF(K56<>"",K56*87.5%,"")
H57: DUPLICADA | K57: =IF(J57<>"",J57*G57,"") | L57: =IF(K57<>"",K57*87.5%,"")
H58: DUPLICADA | K58: =IF(J58<>"",J58*G58,"") | L58: =IF(K58<>"",K58*87.5%,"")
H59: DUPLICADA | K59: =IF(J59<>"",J59*G59,"") | L59: =IF(K59<>"",K59*87.5%,"")
H60: DUPLICADA | K60: =IF(J60<>"",J60*G60,"") | L60: =IF(K60<>"",K60*87.5%,"")
H61: DUPLICADA | K61: =IF(J61<>"",J61*G61,"") | L61: =IF(K61<>"",K61*87.5%,"")
H62: DUPLICADA | K62: =IF(J62<>"",J62*G62,"") | L62: =IF(K62<>"",K62*87.5%,"")
H63: DUPLICADA | K63: =IF(J63<>"",J63*G63,"") | L63: =IF(K63<>"",K63*87.5%,"")
H64: DUPLICADA | K64: =IF(J64<>"",J64*G64,"") | L64: =IF(K64<>"",K64*87.5%,"")
H65: DUPLICADA | K65: =IF(J65<>"",J65*G65,"") | L65: =IF(K65<>"",K65*87.5%,"")
H66: DUPLICADA | K66: =IF(J66<>"",J66*G66,"") | L66: =IF(K66<>"",K66*87.5%,"")
H67: DUPLICADA | K67: =IF(J67<>"",J67*G67,"") | L67: =IF(K67<>"",K67*87.5%,"")
H68: =IFERROR(IF(AND(COUNTIF(RegistroPago!$A$1:$A$2000,Consolidado!B68)>0,INDEX(RegistroPago!$E$1:$E$2000,MATCH(Consolidado!B68,RegistroPago!$A$1:$A$2000,0))<>""),"PAGADA",IF(I68<>"","PENDIENTE","SIN EMITIR")),"") | K68: =IF(J68<>"",J68*G68,"") | L68: =IF(K68<>"",K68*87.5%,"")
H69: ANULADA | K69: =IF(J69<>"",J69*G69,"") | L69: =IF(K69<>"",K69*87.5%,"")
H70: ANULADA | K70: =IF(J70<>"",J70*G70,"") | L70: =IF(K70<>"",K70*87.5%,"")
H71: =IFERROR(IF(AND(COUNTIF(RegistroPago!$A$1:$A$2000,Consolidado!B71)>0,INDEX(RegistroPago!$E$1:$E$2000,MATCH(Consolidado!B71,RegistroPago!$A$1:$A$2000,0))<>""),"PAGADA",IF(I71<>"","PENDIENTE","SIN EMITIR")),"") | K71: =IF(J71<>"",J71*G71,"") | L71: =IF(K71<>"",K71*87.5%,"")
H72: =IFERROR(IF(AND(COUNTIF(RegistroPago!$A$1:$A$2000,Consolidado!B72)>0,INDEX(RegistroPago!$E$1:$E$2000,MATCH(Consolidado!B72,RegistroPago!$A$1:$A$2000,0))<>""),"PAGADA",IF(I72<>"","PENDIENTE","SIN EMITIR")),"") | K72: =IF(J72<>"",J72*G72,"") | L72: =IF(K72<>"",K72*87.5%,"")
H73: =IFERROR(IF(AND(COUNTIF(RegistroPago!$A$1:$A$2000,Consolidado!B73)>0,INDEX(RegistroPago!$E$1:$E$2000,MATCH(Consolidado!B73,RegistroPago!$A$1:$A$2000,0))<>""),"PAGADA",IF(I73<>"","PENDIENTE","SIN EMITIR")),"") | K73: =IF(J73<>"",J73*G73,"") | L73: =IF(K73<>"",K73*87.5%,"")
...

Sheet RegistroPago
A1: Sec. Factura | B1: Mes facturado | C1: Monto facturado | D1: Fecha notificación recibido | E1: Doc mesa dinero | F1: Valor recibido | G1: Días para pago | H1: Doc mesa dinero rep | I1: Valor retenido | J1: % retención | K1: Fecha negociación | L1: TRM negociación | M1: Valor final recibido
A2: {=_xlfn._xlws.SORT(_xlfn.UNIQUE(_xlfn._xlws.FILTER(Consolidado!$B$2:$B$1500,Consolidado!$B$2:$B$1500<>"")))} -> #VALUE! | B2: =IFERROR(VLOOKUP(A2,Consolidado!$B$1:$L$1500,2,FALSE),"") | C2: =IFERROR(SUMIF(Consolidado!$B$1:$B$1500,VLOOKUP(RegistroPago!A2,Consolidado!$B$1:$L$1500,1,FALSE),Consolidado!$G$1:$G$1500),"") -> 0 | G2: =IF(D2<>"",D2-VLOOKUP(A2,Consolidado!$B$1:$L$1500,8,FALSE),"") | H2: {=_xlfn._xlws.SORT(_xlfn.UNIQUE(_xlfn._xlws.FILTER($E$2:$E$2000,$E$2:$E$2000<>"")))} -> #VALUE! | I2: =IFERROR(SUMIF($E$1:$E$2000,H2,$C$1:$C$2000)-SUMIF($E$1:$E$2000,H2,$F$1:$F$2000),"") -> 0 | J2: =IFERROR(I2/SUMIF($E$1:$E$2000,H2,$C$1:$C$2000),"") | M2: =IFERROR(L2*SUMIF($E$1:$E$2000,H2,$F$1:$F$2000),"") -> 0
B3: =IFERROR(VLOOKUP(A3,Consolidado!$B$1:$L$1500,2,FALSE),"") | C3: =IFERROR(SUMIF(Consolidado!$B$1:$B$1500,VLOOKUP(RegistroPago!A3,Consolidado!$B$1:$L$1500,1,FALSE),Consolidado!$G$1:$G$1500),"") -> 0 | G3: =IF(D3<>"",D3-VLOOKUP(A3,Consolidado!$B$1:$L$1500,8,FALSE),"") | I3: =IFERROR(SUMIF($E$1:$E$2000,H3,$C$1:$C$2000)-SUMIF($E$1:$E$2000,H3,$F$1:$F$2000),"") -> 0 | J3: =IFERROR(I3/SUMIF($E$1:$E$2000,H3,$C$1:$C$2000),"") | M3: =IFERROR(L3*SUMIF($E$1:$E$2000,H3,$F$1:$F$2000),"") -> 0
B4: =IFERROR(VLOOKUP(A4,Consolidado!$B$1:$L$1500,2,FALSE),"") | C4: =IFERROR(SUMIF(Consolidado!$B$1:$B$1500,VLOOKUP(RegistroPago!A4,Consolidado!$B$1:$L$1500,1,FALSE),Consolidado!$G$1:$G$1500),"") -> 0 | G4: =IF(D4<>"",D4-VLOOKUP(A4,Consolidado!$B$1:$L$1500,8,FALSE),"") | I4: =IFERROR(SUMIF($E$1:$E$2000,H4,$C$1:$C$2000)-SUMIF($E$1:$E$2000,H4,$F$1:$F$2000),"") -> 0 | J4: =IFERROR(I4/SUMIF($E$1:$E$2000,H4,$C$1:$C$2000),"") | M4: =IFERROR(L4*SUMIF($E$1:$E$2000,H4,$F$1:$F$2000),"") -> 0
B5: =IFERROR(VLOOKUP(A5,Consolidado!$B$1:$L$1500,2,FALSE),"") | C5: =IFERROR(SUMIF(Consolidado!$B$1:$B$1500,VLOOKUP(RegistroPago!A5,Consolidado!$B$1:$L$1500,1,FALSE),Consolidado!$G$1:$G$1500),"") -> 0 | G5: =IF(D5<>"",D5-VLOOKUP(A5,Consolidado!$B$1:$L$1500,8,FALSE),"") | I5: =IFERROR(SUMIF($E$1:$E$2000,H5,$C$1:$C$2000)-SUMIF($E$1:$E$2000,H5,$F$1:$F$2000),"") -> 0 | J5: =IFERROR(I5/SUMIF($E$1:$E$2000,H5,$C$1:$C$2000),"") | M5: =IFERROR(L5*SUMIF($E$1:$E$2000,H5,$F$1:$F$2000),"") -> 0
B6: =IFERROR(VLOOKUP(A6,Consolidado!$B$1:$L$1500,2,FALSE),"") | C6: =IFERROR(SUMIF(Consolidado!$B$1:$B$1500,VLOOKUP(RegistroPago!A6,Consolidado!$B$1:$L$1500,1,FALSE),Consolidado!$G$1:$G$1500),"") -> 0 | G6: =IF(D6<>"",D6-VLOOKUP(A6,Consolidado!$B$1:$L$1500,8,FALSE),"") | I6: =IFERROR(SUMIF($E$1:$E$2000,H6,$C$1:$C$2000)-SUMIF($E$1:$E$2000,H6,$F$1:$F$2000),"") -> 0 | J6: =IFERROR(I6/SUMIF($E$1:$E$2000,H6,$C$1:$C$2000),"") | M6: =IFERROR(L6*SUMIF($E$1:$E$2000,H6,$F$1:$F$2000),"") -> 0
B7: =IFERROR(VLOOKUP(A7,Consolidado!$B$1:$L$1500,2,FALSE),"") | C7: =IFERROR(SUMIF(Consolidado!$B$1:$B$1500,VLOOKUP(RegistroPago!A7,Consolidado!$B$1:$L$1500,1,FALSE),Consolidado!$G$1:$G$1500),"") -> 0 | G7: =IF(D7<>"",D7-VLOOKUP(A7,Consolidado!$B$1:$L$1500,8,FALSE),"") | I7: =IFERROR(SUMIF($E$1:$E$2000,H7,$C$1:$C$2000)-SUMIF($E$1:$E$2000,H7,$F$1:$F$2000),"") -> 0 | J7: =IFERROR(I7/SUMIF($E$1:$E$2000,H7,$C$1:$C$2000),"") | M7: =IFERROR(L7*SUMIF($E$1:$E$2000,H7,$F$1:$F$2000),"") -> 0
B8: =IFERROR(VLOOKUP(A8,Consolidado!$B$1:$L$1500,2,FALSE),"") | C8: =IFERROR(SUMIF(Consolidado!$B$1:$B$1500,VLOOKUP(RegistroPago!A8,Consolidado!$B$1:$L$1500,1,FALSE),Consolidado!$G$1:$G$1500),"") -> 0 | G8: =IF(D8<>"",D8-VLOOKUP(A8,Consolidado!$B$1:$L$1500,8,FALSE),"") | I8: =IFERROR(SUMIF($E$1:$E$2000,H8,$C$1:$C$2000)-SUMIF($E$1:$E$2000,H8,$F$1:$F$2000),"") -> 0 | J8: =IFERROR(I8/SUMIF($E$1:$E$2000,H8,$C$1:$C$2000),"") | M8: =IFERROR(L8*SUMIF($E$1:$E$2000,H8,$F$1:$F$2000),"") -> 0
B9: =IFERROR(VLOOKUP(A9,Consolidado!$B$1:$L$1500,2,FALSE),"") | C9: =IFERROR(SUMIF(Consolidado!$B$1:$B$1500,VLOOKUP(RegistroPago!A9,Consolidado!$B$1:$L$1500,1,FALSE),Consolidado!$G$1:$G$1500),"") -> 0 | G9: =IF(D9<>"",D9-VLOOKUP(A9,Consolidado!$B$1:$L$1500,8,FALSE),"") | I9: =IFERROR(SUMIF($E$1:$E$2000,H9,$C$1:$C$2000)-SUMIF($E$1:$E$2000,H9,$F$1:$F$2000),"") -> 0 | J9: =IFERROR(I9/SUMIF($E$1:$E$2000,H9,$C$1:$C$2000),"") | M9: =IFERROR(L9*SUMIF($E$1:$E$2000,H9,$F$1:$F$2000),"") -> 0
B10: =IFERROR(VLOOKUP(A10,Consolidado!$B$1:$L$1500,2,FALSE),"") | C10: =IFERROR(SUMIF(Consolidado!$B$1:$B$1500,VLOOKUP(RegistroPago!A10,Consolidado!$B$1:$L$1500,1,FALSE),Consolidado!$G$1:$G$1500),"") -> 0 | G10: =IF(D10<>"",D10-VLOOKUP(A10,Consolidado!$B$1:$L$1500,8,FALSE),"") | I10: =IFERROR(SUMIF($E$1:$E$2000,H10,$C$1:$C$2000)-SUMIF($E$1:$E$2000,H10,$F$1:$F$2000),"") -> 0 | J10: =IFERROR(I10/SUMIF($E$1:$E$2000,H10,$C$1:$C$2000),"") | M10: =IFERROR(L10*SUMIF($E$1:$E$2000,H10,$F$1:$F$2000),"") -> 0
B11: =IFERROR(VLOOKUP(A11,Consolidado!$B$1:$L$1500,2,FALSE),"") | C11: =IFERROR(SUMIF(Consolidado!$B$1:$B$1500,VLOOKUP(RegistroPago!A11,Consolidado!$B$1:$L$1500,1,FALSE),Consolidado!$G$1:$G$1500),"") -> 0 | G11: =IF(D11<>"",D11-VLOOKUP(A11,Consolidado!$B$1:$L$1500,8,FALSE),"") | I11: =IFERROR(SUMIF($E$1:$E$2000,H11,$C$1:$C$2000)-SUMIF($E$1:$E$2000,H11,$F$1:$F$2000),"") -> 0 | J11: =IFERROR(I11/SUMIF($E$1:$E$2000,H11,$C$1:$C$2000),"") | M11: =IFERROR(L11*SUMIF($E$1:$E$2000,H11,$F$1:$F$2000),"") -> 0
B12: =IFERROR(VLOOKUP(A12,Consolidado!$B$1:$L$1500,2,FALSE),"") | C12: =IFERROR(SUMIF(Consolidado!$B$1:$B$1500,VLOOKUP(RegistroPago!A12,Consolidado!$B$1:$L$1500,1,FALSE),Consolidado!$G$1:$G$1500),"") -> 0 | G12: =IF(D12<>"",D12-VLOOKUP(A12,Consolidado!$B$1:$L$1500,8,FALSE),"") | I12: =IFERROR(SUMIF($E$1:$E$2000,H12,$C$1:$C$2000)-SUMIF($E$1:$E$2000,H12,$F$1:$F$2000),"") -> 0 | J12: =IFERROR(I12/SUMIF($E$1:$E$2000,H12,$C$1:$C$2000),"") | M12: =IFERROR(L12*SUMIF($E$1:$E$2000,H12,$F$1:$F$2000),"") -> 0
B13: =IFERROR(VLOOKUP(A13,Consolidado!$B$1:$L$1500,2,FALSE),"") | C13: =IFERROR(SUMIF(Consolidado!$B$1:$B$1500,VLOOKUP(RegistroPago!A13,Consolidado!$B$1:$L$1500,1,FALSE),Consolidado!$G$1:$G$1500),"") -> 0 | G13: =IF(D13<>"",D13-VLOOKUP(A13,Consolidado!$B$1:$L$1500,8,FALSE),"") | I13: =IFERROR(SUMIF($E$1:$E$2000,H13,$C$1:$C$2000)-SUMIF($E$1:$E$2000,H13,$F$1:$F$2000),"") -> 0 | J13: =IFERROR(I13/SUMIF($E$1:$E$2000,H13,$C$1:$C$2000),"") | M13: =IFERROR(L13*SUMIF($E$1:$E$2000,H13,$F$1:$F$2000),"") -> 0
B14: =IFERROR(VLOOKUP(A14,Consolidado!$B$1:$L$1500,2,FALSE),"") | C14: =IFERROR(SUMIF(Consolidado!$B$1:$B$1500,VLOOKUP(RegistroPago!A14,Consolidado!$B$1:$L$1500,1,FALSE),Consolidado!$G$1:$G$1500),"") -> 0 | G14: =IF(D14<>"",D14-VLOOKUP(A14,Consolidado!$B$1:$L$1500,8,FALSE),"") | I14: =IFERROR(SUMIF($E$1:$E$2000,H14,$C$1:$C$2000)-SUMIF($E$1:$E$2000,H14,$F$1:$F$2000),"") -> 0 | J14: =IFERROR(I14/SUMIF($E$1:$E$2000,H14,$C$1:$C$2000),"") | M14: =IFERROR(L14*SUMIF($E$1:$E$2000,H14,$F$1:$F$2000),"") -> 0
... B25: =IFERROR(VLOOKUP(A25,Consolidado!$B$1:$L$1500,2,FALSE),"") | C25: =IFERROR(SUMIF(Consolidado!$B$1:$B$1500,VLOOKUP(RegistroPago!A25,Consolidado!$B$1:$L$1500,1,FALSE),Consolidado!$G$1:$G$1500),"") -> 0 | G25: =IF(D25<>"",D25-VLOOKUP(A25,Consolidado!$B$1:$L$1500,8,FALSE),"") | I25: =IFERROR(SUMIF($E$1:$E$2000,H25,$C$1:$C$2000)-SUMIF($E$1:$E$2000,H25,$F$1:$F$2000),"") -> 0 | J25: =IFERROR(I25/SUMIF($E$1:$E$2000,H25,$C$1:$C$2000),"") | M25: =IFERROR(L25*SUMIF($E$1:$E$2000,H25,$F$1:$F$2000),"") -> 0
B26: =IFERROR(VLOOKUP(A26,Consolidado!$B$1:$L$1500,2,FALSE),"") | C26: =IFERROR(SUMIF(Consolidado!$B$1:$B$1500,VLOOKUP(RegistroPago!A26,Consolidado!$B$1:$L$1500,1,FALSE),Consolidado!$G$1:$G$1500),"") -> 0 | F26: =IF(COUNTIF($E$2:$E$2000,E26)>1,"Ya registrado","") | G26: =IF(D26<>"",D26-VLOOKUP(A26,Consolidado!$B$1:$L$1500,8,FALSE),"") | I26: =IFERROR(SUMIF($E$1:$E$2000,H26,$C$1:$C$2000)-SUMIF($E$1:$E$2000,H26,$F$1:$F$2000),"") -> 0 | J26: =IFERROR(I26/SUMIF($E$1:$E$2000,H26,$C$1:$C$2000),"") | M26: =IFERROR(L26*SUMIF($E$1:$E$2000,H26,$F$1:$F$2000),"") -> 0
B27: =IFERROR(VLOOKUP(A27,Consolidado!$B$1:$L$1500,2,FALSE),"") | C27: =IFERROR(SUMIF(Consolidado!$B$1:$B$1500,VLOOKUP(RegistroPago!A27,Consolidado!$B$1:$L$1500,1,FALSE),Consolidado!$G$1:$G$1500),"") -> 0 | G27: =IF(D27<>"",D27-VLOOKUP(A27,Consolidado!$B$1:$L$1500,8,FALSE),"") | I27: =IFERROR(SUMIF($E$1:$E$2000,H27,$C$1:$C$2000)-SUMIF($E$1:$E$2000,H27,$F$1:$F$2000),"") -> 0 | J27: =IFERROR(I27/SUMIF($E$1:$E$2000,H27,$C$1:$C$2000),"") | M27: =IFERROR(L27*SUMIF($E$1:$E$2000,H27,$F$1:$F$2000),"") -> 0
B28: =IFERROR(VLOOKUP(A28,Consolidado!$B$1:$L$1500,2,FALSE),"") | C28: =IFERROR(SUMIF(Consolidado!$B$1:$B$1500,VLOOKUP(RegistroPago!A28,Consolidado!$B$1:$L$1500,1,FALSE),Consolidado!$G$1:$G$1500),"") -> 0 | G28: =IF(D28<>"",D28-VLOOKUP(A28,Consolidado!$B$1:$L$1500,8,FALSE),"") | I28: =IFERROR(SUMIF($E$1:$E$2000,H28,$C$1:$C$2000)-SUMIF($E$1:$E$2000,H28,$F$1:$F$2000),"") -> 0 | J28: =IFERROR(I28/SUMIF($E$1:$E$2000,H28,$C$1:$C$2000),"") | M28: =IFERROR(L28*SUMIF($E$1:$E$2000,H28,$F$1:$F$2000),"") -> 0
B29: =IFERROR(VLOOKUP(A29,Consolidado!$B$1:$L$1500,2,FALSE),"") | C29: =IFERROR(SUMIF(Consolidado!$B$1:$B$1500,VLOOKUP(RegistroPago!A29,Consolidado!$B$1:$L$1500,1,FALSE),Consolidado!$G$1:$G$1500),"") -> 0 | G29: =IF(D29<>"",D29-VLOOKUP(A29,Consolidado!$B$1:$L$1500,8,FALSE),"") | I29: =IFERROR(SUMIF($E$1:$E$2000,H29,$C$1:$C$2000)-SUMIF($E$1:$E$2000,H29,$F$1:$F$2000),"") -> 0 | J29: =IFERROR(I29/SUMIF($E$1:$E$2000,H29,$C$1:$C$2000),"") | M29: =IFERROR(L29*SUMIF($E$1:$E$2000,H29,$F$1:$F$2000),"") -> 0
B30: =IFERROR(VLOOKUP(A30,Consolidado!$B$1:$L$1500,2,FALSE),"") | C30: =IFERROR(SUMIF(Consolidado!$B$1:$B$1500,VLOOKUP(RegistroPago!A30,Consolidado!$B$1:$L$1500,1,FALSE),Consolidado!$G$1:$G$1500),"") -> 0 | G30: =IF(D30<>"",D30-VLOOKUP(A30,Consolidado!$B$1:$L$1500,8,FALSE),"") | I30: =IFERROR(SUMIF($E$1:$E$2000,H30,$C$1:$C$2000)-SUMIF($E$1:$E$2000,H30,$F$1:$F$2000),"") -> 0 | J30: =IFERROR(I30/SUMIF($E$1:$E$2000,H30,$C$1:$C$2000),"") | M30: =IFERROR(L30*SUMIF($E$1:$E$2000,H30,$F$1:$F$2000),"") -> 0
B31: =IFERROR(VLOOKUP(A31,Consolidado!$B$1:$L$1500,2,FALSE),"") | C31: =IFERROR(SUMIF(Consolidado!$B$1:$B$1500,VLOOKUP(RegistroPago!A31,Consolidado!$B$1:$L$1500,1,FALSE),Consolidado!$G$1:$G$1500),"") -> 0 | G31: =IF(D31<>"",D31-VLOOKUP(A31,Consolidado!$B$1:$L$1500,8,FALSE),"") | I31: =IFERROR(SUMIF($E$1:$E$2000,H31,$C$1:$C$2000)-SUMIF($E$1:$E$2000,H31,$F$1:$F$2000),"") -> 0 | J31: =IFERROR(I31/SUMIF($E$1:$E$2000,H31,$C$1:$C$2000),"") | M31: =IFERROR(L31*SUMIF($E$1:$E$2000,H31,$F$1:$F$2000),"") -> 0
B32: =IFERROR(VLOOKUP(A32,Consolidado!$B$1:$L$1500,2,FALSE),"") | C32: =IFERROR(SUMIF(Consolidado!$B$1:$B$1500,VLOOKUP(RegistroPago!A32,Consolidado!$B$1:$L$1500,1,FALSE),Consolidado!$G$1:$G$1500),"") -> 0 | G32: =IF(D32<>"",D32-VLOOKUP(A32,Consolidado!$B$1:$L$1500,8,FALSE),"") | I32: =IFERROR(SUMIF($E$1:$E$2000,H32,$C$1:$C$2000)-SUMIF($E$1:$E$2000,H32,$F$1:$F$2000),"") -> 0 | J32: =IFERROR(I32/SUMIF($E$1:$E$2000,H32,$C$1:$C$2000),"") | M32: =IFERROR(L32*SUMIF($E$1:$E$2000,H32,$F$1:$F$2000),"") -> 0
B33: =IFERROR(VLOOKUP(A33,Consolidado!$B$1:$L$1500,2,FALSE),"") | C33: =IFERROR(SUMIF(Consolidado!$B$1:$B$1500,VLOOKUP(RegistroPago!A33,Consolidado!$B$1:$L$1500,1,FALSE),Consolidado!$G$1:$G$1500),"") -> 0 | F33: =IF(COUNTIF($E$2:$E$2000,E33)>1,"Ya registrado","") | G33: =IF(D33<>"",D33-VLOOKUP(A33,Consolidado!$B$1:$L$1500,8,FALSE),"") | I33: =IFERROR(SUMIF($E$1:$E$2000,H33,$C$1:$C$2000)-SUMIF($E$1:$E$2000,H33,$F$1:$F$2000),"") -> 0 | J33: =IFERROR(I33/SUMIF($E$1:$E$2000,H33,$C$1:$C$2000),"") | M33: =IFERROR(L33*SUMIF($E$1:$E$2000,H33,$F$1:$F$2000),"") -> 0
B34: =IFERROR(VLOOKUP(A34,Consolidado!$B$1:$L$1500,2,FALSE),"") | C34: =IFERROR(SUMIF(Consolidado!$B$1:$B$1500,VLOOKUP(RegistroPago!A34,Consolidado!$B$1:$L$1500,1,FALSE),Consolidado!$G$1:$G$1500),"") -> 0 | F34: =IF(COUNTIF($E$2:$E$2000,E34)>1,"Ya registrado","") | G34: =IF(D34<>"",D34-VLOOKUP(A34,Consolidado!$B$1:$L$1500,8,FALSE),"") | I34: =IFERROR(SUMIF($E$1:$E$2000,H34,$C$1:$C$2000)-SUMIF($E$1:$E$2000,H34,$F$1:$F$2000),"") -> 0 | J34: =IFERROR(I34/SUMIF($E$1:$E$2000,H34,$C$1:$C$2000),"") | M34: =IFERROR(L34*SUMIF($E$1:$E$2000,H34,$F$1:$F$2000),"") -> 0
B35: =IFERROR(VLOOKUP(A35,Consolidado!$B$1:$L$1500,2,FALSE),"") | C35: =IFERROR(SUMIF(Consolidado!$B$1:$B$1500,VLOOKUP(RegistroPago!A35,Consolidado!$B$1:$L$1500,1,FALSE),Consolidado!$G$1:$G$1500),"") -> 0 | F35: =IF(COUNTIF($E$2:$E$2000,E35)>1,"Ya registrado","") | G35: =IF(D35<>"",D35-VLOOKUP(A35,Consolidado!$B$1:$L$1500,8,FALSE),"") | I35: =IFERROR(SUMIF($E$1:$E$2000,H35,$C$1:$C$2000)-SUMIF($E$1:$E$2000,H35,$F$1:$F$2000),"") -> 0 | J35: =IFERROR(I35/SUMIF($E$1:$E$2000,H35,$C$1:$C$2000),"") | M35: =IFERROR(L35*SUMIF($E$1:$E$2000,H35,$F$1:$F$2000),"") -> 0
B36: =IFERROR(VLOOKUP(A36,Consolidado!$B$1:$L$1500,2,FALSE),"") | C36: =IFERROR(SUMIF(Consolidado!$B$1:$B$1500,VLOOKUP(RegistroPago!A36,Consolidado!$B$1:$L$1500,1,FALSE),Consolidado!$G$1:$G$1500),"") -> 0 | F36: =IF(COUNTIF($E$2:$E$2000,E36)>1,"Ya registrado","") | G36: =IF(D36<>"",D36-VLOOKUP(A36,Consolidado!$B$1:$L$1500,8,FALSE),"") | I36: =IFERROR(SUMIF($E$1:$E$2000,H36,$C$1:$C$2000)-SUMIF($E$1:$E$2000,H36,$F$1:$F$2000),"") -> 0 | J36: =IFERROR(I36/SUMIF($E$1:$E$2000,H36,$C$1:$C$2000),"") | M36: =IFERROR(L36*SUMIF($E$1:$E$2000,H36,$F$1:$F$2000),"") -> 0
B37: =IFERROR(VLOOKUP(A37,Consolidado!$B$1:$L$1500,2,FALSE),"") | C37: =IFERROR(SUMIF(Consolidado!$B$1:$B$1500,VLOOKUP(RegistroPago!A37,Consolidado!$B$1:$L$1500,1,FALSE),Consolidado!$G$1:$G$1500),"") -> 0 | F37: =IF(COUNTIF($E$2:$E$2000,E37)>1,"Ya registrado","") | G37: =IF(D37<>"",D37-VLOOKUP(A37,Consolidado!$B$1:$L$1500,8,FALSE),"") | I37: =IFERROR(SUMIF($E$1:$E$2000,H37,$C$1:$C$2000)-SUMIF($E$1:$E$2000,H37,$F$1:$F$2000),"") -> 0 | J37: =IFERROR(I37/SUMIF($E$1:$E$2000,H37,$C$1:$C$2000),"") | M37: =IFERROR(L37*SUMIF($E$1:$E$2000,H37,$F$1:$F$2000),"") -> 0
B38: =IFERROR(VLOOKUP(A38,Consolidado!$B$1:$L$1500,2,FALSE),"") | C38: =IFERROR(SUMIF(Consolidado!$B$1:$B$1500,VLOOKUP(RegistroPago!A38,Consolidado!$B$1:$L$1500,1,FALSE),Consolidado!$G$1:$G$1500),"") -> 0 | F38: =IF(COUNTIF($E$2:$E$2000,E38)>1,"Ya registrado","") | G38: =IF(D38<>"",D38-VLOOKUP(A38,Consolidado!$B$1:$L$1500,8,FALSE),"") | I38: =IFERROR(SUMIF($E$1:$E$2000,H38,$C$1:$C$2000)-SUMIF($E$1:$E$2000,H38,$F$1:$F$2000),"") -> 0 | J38: =IFERROR(I38/SUMIF($E$1:$E$2000,H38,$C$1:$C$2000),"") | M38: =IFERROR(L38*SUMIF($E$1:$E$2000,H38,$F$1:$F$2000),"") -> 0
B39: =IFERROR(VLOOKUP(A39,Consolidado!$B$1:$L$1500,2,FALSE),"") | C39: =IFERROR(SUMIF(Consolidado!$B$1:$B$1500,VLOOKUP(RegistroPago!A39,Consolidado!$B$1:$L$1500,1,FALSE),Consolidado!$G$1:$G$1500),"") -> 0 | F39: =IF(COUNTIF($E$2:$E$2000,E39)>1,"Ya registrado","") | G39: =IF(D39<>"",D39-VLOOKUP(A39,Consolidado!$B$1:$L$1500,8,FALSE),"") | I39: =IFERROR(SUMIF($E$1:$E$2000,H39,$C$1:$C$2000)-SUMIF($E$1:$E$2000,H39,$F$1:$F$2000),"") -> 0 | J39: =IFERROR(I39/SUMIF($E$1:$E$2000,H39,$C$1:$C$2000),"") | M39: =IFERROR(L39*SUMIF($E$1:$E$2000,H39,$F$1:$F$2000),"") -> 0
B40: =IFERROR(VLOOKUP(A40,Consolidado!$B$1:$L$1500,2,FALSE),"") | C40: =IFERROR(SUMIF(Consolidado!$B$1:$B$1500,VLOOKUP(RegistroPago!A40,Consolidado!$B$1:$L$1500,1,FALSE),Consolidado!$G$1:$G$1500),"") -> 0 | F40: =IF(COUNTIF($E$2:$E$2000,E40)>1,"Ya registrado","") | G40: =IF(D40<>"",D40-VLOOKUP(A40,Consolidado!$B$1:$L$1500,8,FALSE),"") | I40: =IFERROR(SUMIF($E$1:$E$2000,H40,$C$1:$C$2000)-SUMIF($E$1:$E$2000,H40,$F$1:$F$2000),"") -> 0 | J40: =IFERROR(I40/SUMIF($E$1:$E$2000,H40,$C$1:$C$2000),"") | M40: =IFERROR(L40*SUMIF($E$1:$E$2000,H40,$F$1:$F$2000),"") -> 0
B41: =IFERROR(VLOOKUP(A41,Consolidado!$B$1:$L$1500,2,FALSE),"") | C41: =IFERROR(SUMIF(Consolidado!$B$1:$B$1500,VLOOKUP(RegistroPago!A41,Consolidado!$B$1:$L$1500,1,FALSE),Consolidado!$G$1:$G$1500),"") -> 0 | F41: =IF(COUNTIF($E$2:$E$2000,E41)>1,"Ya registrado","") | G41: =IF(D41<>"",D41-VLOOKUP(A41,Consolidado!$B$1:$L$1500,8,FALSE),"") | I41: =IFERROR(SUMIF($E$1:$E$2000,H41,$C$1:$C$2000)-SUMIF($E$1:$E$2000,H41,$F$1:$F$2000),"") -> 0 | J41: =IFERROR(I41/SUMIF($E$1:$E$2000,H41,$C$1:$C$2000),"") | M41: =IFERROR(L41*SUMIF($E$1:$E$2000,H41,$F$1:$F$2000),"") -> 0
B42: =IFERROR(VLOOKUP(A42,Consolidado!$B$1:$L$1500,2,FALSE),"") | C42: =IFERROR(SUMIF(Consolidado!$B$1:$B$1500,VLOOKUP(RegistroPago!A42,Consolidado!$B$1:$L$1500,1,FALSE),Consolidado!$G$1:$G$1500),"") -> 0 | F42: =IF(COUNTIF($E$2:$E$2000,E42)>1,"Ya registrado","") | G42: =IF(D42<>"",D42-VLOOKUP(A42,Consolidado!$B$1:$L$1500,8,FALSE),"") | I42: =IFERROR(SUMIF($E$1:$E$2000,H42,$C$1:$C$2000)-SUMIF($E$1:$E$2000,H42,$F$1:$F$2000),"") -> 0 | J42: =IFERROR(I42/SUMIF($E$1:$E$2000,H42,$C$1:$C$2000),"") | M42: =IFERROR(L42*SUMIF($E$1:$E$2000,H42,$F$1:$F$2000),"") -> 0
B43: =IFERROR(VLOOKUP(A43,Consolidado!$B$1:$L$1500,2,FALSE),"") | C43: =IFERROR(SUMIF(Consolidado!$B$1:$B$1500,VLOOKUP(RegistroPago!A43,Consolidado!$B$1:$L$1500,1,FALSE),Consolidado!$G$1:$G$1500),"") -> 0 | F43: =IF(COUNTIF($E$2:$E$2000,E43)>1,"Ya registrado","") | G43: =IF(D43<>"",D43-VLOOKUP(A43,Consolidado!$B$1:$L$1500,8,FALSE),"") | I43: =IFERROR(SUMIF($E$1:$E$2000,H43,$C$1:$C$2000)-SUMIF($E$1:$E$2000,H43,$F$1:$F$2000),"") -> 0 | J43: =IFERROR(I43/SUMIF($E$1:$E$2000,H43,$C$1:$C$2000),"") | M43: =IFERROR(L43*SUMIF($E$1:$E$2000,H43,$F$1:$F$2000),"") -> 0
B44: =IFERROR(VLOOKUP(A44,Consolidado!$B$1:$L$1500,2,FALSE),"") | C44: =IFERROR(SUMIF(Consolidado!$B$1:$B$1500,VLOOKUP(RegistroPago!A44,Consolidado!$B$1:$L$1500,1,FALSE),Consolidado!$G$1:$G$1500),"") -> 0 | F44: =IF(COUNTIF($E$2:$E$2000,E44)>1,"Ya registrado","") | G44: =IF(D44<>"",D44-VLOOKUP(A44,Consolidado!$B$1:$L$1500,8,FALSE),"") | I44: =IFERROR(SUMIF($E$1:$E$2000,H44,$C$1:$C$2000)-SUMIF($E$1:$E$2000,H44,$F$1:$F$2000),"") -> 0 | J44: =IFERROR(I44/SUMIF($E$1:$E$2000,H44,$C$1:$C$2000),"") | M44: =IFERROR(L44*SUMIF($E$1:$E$2000,H44,$F$1:$F$2000),"") -> 0
... B2000: =IFERROR(VLOOKUP(A2000,Consolidado!$B$1:$L$1500,2,FALSE),"") | C2000: =IFERROR(SUMIF(Consolidado!$B$1:$B$1500,VLOOKUP(RegistroPago!A2000,Consolidado!$B$1:$L$1500,1,FALSE),Consolidado!$G$1:$G$1500),"") -> 0 | F2000: =IF(COUNTIF($E$2:$E$2000,E2000)>1,"Ya registrado","") | G2000: =IF(D2000<>"",D2000-VLOOKUP(A2000,Consolidado!$B$1:$L$1500,8,FALSE),"") | I2000: =IFERROR(SUMIF($E$1:$E$2000,H2000,$C$1:$C$2000)-SUMIF($E$1:$E$2000,H2000,$F$1:$F$2000),"") -> 0 | J2000: =IFERROR(I2000/SUMIF($E$1:$E$2000,H2000,$C$1:$C$2000),"") | M2000: =IFERROR(L2000*SUMIF($E$1:$E$2000,H2000,$F$1:$F$2000),"") -> 0

Sheet KPI´s
A1: Etiquetas de fila | B1: Suma de Monto facturado | C1: Suma de Valor recibido
A2: ENERO | B2: 99206.677 | C2: 90716.47
A3: FEBRERO | B3: 153587.76 | C3: 84987.52
A4: MARZO | B4: 134876.99 | C4: 0
A5: ABRIL | B5: 42841.642 | C5: 0
B6: 0 | C6: 0
A7: Total general | B7: 430513.07 | C7: 175703.99
A18: Etiquetas de fila | B18: Promedio de Días para pago
A19: ENERO | B19: 20.785714
A20: FEBRERO | B20: 11.625
A21: MARZO | B21: #DIV/0!
A22: ABRIL | B22: #DIV/0!
B23: #DIV/0!
A24: Total general | B24: 15.9
A35: Etiquetas de fila | B35: Suma de Valor final recibido
A36: mar | B36: 2.8855838e+08
A37: Total general | B37: 2.8855838e+08
A50: Etiquetas de fila | B50: Suma de Monto COP reportado DIAN | C50: Suma de Monto COP esperado
A51: ENERO | B51: 3.641887e+08 | C51: 3.1866511e+08
A52: FEBRERO | B52: 4.7077694e+08 | C52: 4.1192982e+08
A53: MARZO | B53: 0 | C53: 0
A54: ABRIL | B54: 0 | C54: 0
A55: Total general | B55: 8.3496564e+08 | C55: 7.3059493e+08
A66: Etiquetas de fila | B66: Cuenta de Estado
A67: SIN EMITIR | B67: 0.01754386
A68: DUPLICADA | B68: 0.10526316
A69: PAGADA | B69: 0.45614035
A70: ANULADA | B70: 0.026315789
A71: PENDIENTE | B71: 0.39473684
A72: Total general | B72: 1
A78: Etiquetas de fila | B78: Suma de Monto facturado
A79: Banistmo | B79: 430513.07
A80: Total general | B80: 430513.07
