Workbook

Sheet TALENTOS BEE
A1: Libro: Nuevo reporte de Maestro de empleados Novedades
A2: Fecha Generación: 20/05/2026 a las 09:19AM
A3: FECHA DESDE | B3: 46143 | C3: =MONTH(B3) -> 5
A4: FECHA HASTA | B4: 46173 | C4: =MONTH(B4) -> 5
A6: Empresa | B6: TIPO CONTRATO | C6: Colaborador - Nombre Completo | D6: Fecha de Nacimiento | E6: BONO CUMPLEAÑOS | F6: Fecha Ingreso Compañía | G6: INCREMENTO SALARIAL | H6: Pais Ubicación | I6: Moneda de Pago | J6: Colaborador - Salario | K6: Banco de cuenta a pagar | L6: # Cuenta a pagar
A7: BEE Consultoria y Negocios | B7: INDEFINIDO | C7: Álvarez Velásquez Sergio Andrés | D7: 31207 | E7: =IF(MONTH(D7)=$C$3,"SI","NO") -> NO | F7: 44599 | G7: =IF(AND(YEAR($B$3)-YEAR(F7)>0,MONTH(F7)=$C$3),"SI","NO") -> NO | H7: Colombia | I7: COP | J7: 5500000 | K7: BANCOLOMBIA - AHO | L7: 52017092154
A8: BEE Consultoria y Negocios | B8: INDEFINIDO | C8: Ballesteros Jonathan Hans | D8: 32408 | E8: =IF(MONTH(D8)=$C$3,"SI","NO") -> NO | F8: 46083 | G8: =IF(AND(YEAR($B$3)-YEAR(F8)>0,MONTH(F8)=$C$3),"SI","NO") -> NO | H8: Colombia | I8: COP | J8: 6000000 | K8: BANCOLOMBIA - AHO | L8: 66146626379
A9: BEE Consultoria y Negocios | B9: INDEFINIDO | C9: Bohorquez Rodríguez Esteban | D9: 38113 | E9: =IF(MONTH(D9)=$C$3,"SI","NO") -> SI | F9: 46097 | G9: =IF(AND(YEAR($B$3)-YEAR(F9)>0,MONTH(F9)=$C$3),"SI","NO") -> NO | H9: Colombia | I9: COP | J9: 7000000 | K9: BANCOLOMBIA - AHO | L9: 59644896409
A10: BEE Consultoria y Negocios | B10: PRESTACION DE SERVICIOS | C10: Briceño Pinilla John Sebastian | D10: 32845 | E10: =IF(MONTH(D10)=$C$3,"SI","NO") -> NO | F10: 44995 | G10: =IF(AND(YEAR($B$3)-YEAR(F10)>0,MONTH(F10)=$C$3),"SI","NO") -> NO | H10: Colombia | I10: COP | J10: 15000000 | K10: NU BANK- AHO | L10: 35981518
A11: BEE Consultoria y Negocios | B11: INDEFINIDO | C11: Caicedo Álvarez Kevin | D11: 34964 | E11: =IF(MONTH(D11)=$C$3,"SI","NO") -> NO | F11: 45537 | G11: =IF(AND(YEAR($B$3)-YEAR(F11)>0,MONTH(F11)=$C$3),"SI","NO") -> NO | H11: Colombia | I11: COP | J11: 6032000 | K11: BANCOLOMBIA - AHO | L11: 37783106397
A12: BEE Consultoria y Negocios | B12: PRESTACION DE SERVICIOS | C12: Castro Portilla Alexander Fabricio | D12: 35246 | E12: =IF(MONTH(D12)=$C$3,"SI","NO") -> NO | F12: 46125 | G12: =IF(AND(YEAR($B$3)-YEAR(F12)>0,MONTH(F12)=$C$3),"SI","NO") -> NO | H12: ECUADOR | I12: USD | J12: 1900 | K12: BANCO DEL PICHINCHA - AHO | L12: 2208340614
A13: BEE Consultoria y Negocios | B13: PRESTACION DE SERVICIOS | C13: Chávez García Nicole Yadira | D13: 35671 | E13: =IF(MONTH(D13)=$C$3,"SI","NO") -> NO | F13: 46076 | G13: =IF(AND(YEAR($B$3)-YEAR(F13)>0,MONTH(F13)=$C$3),"SI","NO") -> NO | H13: ECUADOR | I13: USD | J13: 2100 | K13: BANCO DEL PICHINCHA - AHO | L13: 2200097976
A14: BEE Consultoria y Negocios | B14: PRESTACION DE SERVICIOS | C14: Díaz Rosero Carlos Joel | D14: 34229 | E14: =IF(MONTH(D14)=$C$3,"SI","NO") -> NO | F14: 45597 | G14: =IF(AND(YEAR($B$3)-YEAR(F14)>0,MONTH(F14)=$C$3),"SI","NO") -> NO | H14: ECUADOR | I14: USD | J14: 2080 | K14: BANCO DEL PICHINCHA - AHO | L14: 2201988417
A15: BEE Consultoria y Negocios | B15: INDEFINIDO | C15: Díaz Vargas Aneyda Raquel | D15: 27133 | E15: =IF(MONTH(D15)=$C$3,"SI","NO") -> NO | F15: 45614 | G15: =IF(AND(YEAR($B$3)-YEAR(F15)>0,MONTH(F15)=$C$3),"SI","NO") -> NO | H15: Colombia | I15: COP | J15: 9360000 | K15: BANCOLOMBIA - AHO | L15: 1348571121
A16: BEE Consultoria y Negocios | B16: INDEFINIDO | C16: Duque Cortes Estiward Alexander | D16: 34827 | E16: =IF(MONTH(D16)=$C$3,"SI","NO") -> SI | F16: 46121 | G16: =IF(AND(YEAR($B$3)-YEAR(F16)>0,MONTH(F16)=$C$3),"SI","NO") -> NO | H16: Colombia | I16: COP | J16: 6500000 | K16: BANCO DE BOGOTA - AHO | L16: 309189298
A17: BEE Consultoria y Negocios | B17: PRESTACION DE SERVICIOS | C17: Espinoza Carua Jefferson David | D17: 34352 | E17: =IF(MONTH(D17)=$C$3,"SI","NO") -> NO | F17: 45855 | G17: =IF(AND(YEAR($B$3)-YEAR(F17)>0,MONTH(F17)=$C$3),"SI","NO") -> NO | H17: ECUADOR | I17: USD | J17: 2000 | K17: BANCO DEL PICHINCHA - AHO | L17: 2208390652
A18: BEE Consultoria y Negocios | B18: PRESTACION DE SERVICIOS | C18: García Regalado Pratt Christian | D18: 36753 | E18: =IF(MONTH(D18)=$C$3,"SI","NO") -> NO | F18: 46079 | G18: =IF(AND(YEAR($B$3)-YEAR(F18)>0,MONTH(F18)=$C$3),"SI","NO") -> NO | H18: ECUADOR | I18: USD | J18: 1900 | K18: BANCO DEL PICHINCHA - AHO | L18: 2208798444
A19: BEE Consultoria y Negocios | B19: INDEFINIDO | C19: Granada Ramírez Luisa Fernanda | D19: 33927 | E19: =IF(MONTH(D19)=$C$3,"SI","NO") -> NO | F19: 45880 | G19: =IF(AND(YEAR($B$3)-YEAR(F19)>0,MONTH(F19)=$C$3),"SI","NO") -> NO | H19: Colombia | I19: COP | J19: 5000000 | K19: BANCOLOMBIA - AHO | L19: 62300005603
A20: BEE Consultoria y Negocios | B20: INDEFINIDO | C20: Hoyos Florez Octavio | D20: 26847 | E20: =IF(MONTH(D20)=$C$3,"SI","NO") -> NO | F20: 45839 | G20: =IF(AND(YEAR($B$3)-YEAR(F20)>0,MONTH(F20)=$C$3),"SI","NO") -> NO | H20: Colombia | I20: COP | J20: 30500000 | K20: DAVIBANK - AHO | L20: 5582075028
A21: BEE Consultoria y Negocios | B21: PRESTACION DE SERVICIOS | C21: Idrovo Campaña Byron Andrés | D21: 33778 | E21: =IF(MONTH(D21)=$C$3,"SI","NO") -> NO | F21: 46121 | G21: =IF(AND(YEAR($B$3)-YEAR(F21)>0,MONTH(F21)=$C$3),"SI","NO") -> NO | H21: ECUADOR | I21: USD | J21: 1900 | K21: BANCO DEL PICHINCHA - AHO | L21: 2202909156
A22: Bee Consultoría & Negocios | B22: INDEFINIDO | C22: Leal Marín Edyson Fabian | D22: 34421 | E22: =IF(MONTH(D22)=$C$3,"SI","NO") -> NO | F22: 46149 | G22: =IF(AND(YEAR($B$3)-YEAR(F22)>0,MONTH(F22)=$C$3),"SI","NO") -> NO | H22: Colombia | I22: COP | J22: 6500000 | K22: Banco de Bogotá | L22: 601605355
A23: BEE Consultoria y Negocios | B23: PRESTACION DE SERVICIOS | C23: Loor Moran Aaron Wladimir | D23: 35964 | E23: =IF(MONTH(D23)=$C$3,"SI","NO") -> NO | F23: 45835 | G23: =IF(AND(YEAR($B$3)-YEAR(F23)>0,MONTH(F23)=$C$3),"SI","NO") -> NO | H23: ECUADOR | I23: USD | J23: 2400 | K23: PRODUBANCO - AHO | L23: 20300969714
A24: BEE Consultoria y Negocios | B24: PRESTACION DE SERVICIOS | C24: López Cárdenas Stiven Oswaldo | D24: 36577 | E24: =IF(MONTH(D24)=$C$3,"SI","NO") -> NO | F24: 45854 | G24: =IF(AND(YEAR($B$3)-YEAR(F24)>0,MONTH(F24)=$C$3),"SI","NO") -> NO | H24: ECUADOR | I24: USD | J24: 2000 | K24: BANCO DEL PICHINCHA - AHO | L24: 2206943004
A25: BEE Consultoria y Negocios | B25: PRESTACION DE SERVICIOS | C25: Mafla Jarrín Martín Alejandro | D25: 37724 | E25: =IF(MONTH(D25)=$C$3,"SI","NO") -> NO | F25: 46097 | G25: =IF(AND(YEAR($B$3)-YEAR(F25)>0,MONTH(F25)=$C$3),"SI","NO") -> NO | H25: ECUADOR | I25: USD | J25: 1900 | K25: BANCO DEL PICHINCHA - AHO | L25: 2209823719
A26: BEE Consultoria y Negocios | B26: PRESTACION DE SERVICIOS | C26: Mafla Montoya Vicente Amilcar | D26: 25329 | E26: =IF(MONTH(D26)=$C$3,"SI","NO") -> SI | F26: 45341 | G26: =IF(AND(YEAR($B$3)-YEAR(F26)>0,MONTH(F26)=$C$3),"SI","NO") -> NO | H26: ECUADOR | I26: USD | J26: 4000 | K26: BANCO DEL PICHINCHA - AHO | L26: 2208459330
A27: BEE Consultoria y Negocios | B27: PRESTACION DE SERVICIOS | C27: Medina Choque Víctor Fernando | D27: 28440 | E27: =IF(MONTH(D27)=$C$3,"SI","NO") -> NO | F27: 46085 | G27: =IF(AND(YEAR($B$3)-YEAR(F27)>0,MONTH(F27)=$C$3),"SI","NO") -> NO | H27: ARGENTINA | I27: USD | J27: 3200 | K27: GLOBAL66 | L27: VICMED628
A28: BEE Consultoria y Negocios | B28: INDEFINIDO | C28: Mena Salcedo Johnatan Alexander | D28: 33554 | E28: =IF(MONTH(D28)=$C$3,"SI","NO") -> NO | F28: 45475 | G28: =IF(AND(YEAR($B$3)-YEAR(F28)>0,MONTH(F28)=$C$3),"SI","NO") -> NO | H28: Colombia | I28: COP | J28: 6760000 | K28: BANCOLOMBIA AHO | L28: 00912571289
A29: BEE Consultoria y Negocios | B29: PRESTACION DE SERVICIOS | C29: Monteros González Kevin Joel | D29: 36425 | E29: =IF(MONTH(D29)=$C$3,"SI","NO") -> NO | F29: 45855 | G29: =IF(AND(YEAR($B$3)-YEAR(F29)>0,MONTH(F29)=$C$3),"SI","NO") -> NO | H29: ECUADOR | I29: USD | J29: 2000 | K29: BANCO DEL PICHINCHA - A | L29: 2207974233
A30: BEE Consultoria y Negocios | B30: PRESTACION DE SERVICIOS | C30: Nicolalde Perugachi Joana Estefanía | D30: 36092 | E30: =IF(MONTH(D30)=$C$3,"SI","NO") -> NO | F30: 45597 | G30: =IF(AND(YEAR($B$3)-YEAR(F30)>0,MONTH(F30)=$C$3),"SI","NO") -> NO | H30: ECUADOR | I30: USD | J30: 2080 | K30: BANCO DEL PICHINCHA - AHO | L30: 2203559686
A31: BEE Consultoria y Negocios | B31: PRESTACION DE SERVICIOS | C31: Olivo Revelo Kevin Eduardo | D31: 35962 | E31: =IF(MONTH(D31)=$C$3,"SI","NO") -> NO | F31: 45910 | G31: =IF(AND(YEAR($B$3)-YEAR(F31)>0,MONTH(F31)=$C$3),"SI","NO") -> NO | H31: ECUADOR | I31: USD | J31: 2000 | K31: BANCO DEL PICHINCHA - AHO | L31: 2202913708
A32: BEE Consultoria y Negocios | B32: PRESTACION DE SERVICIOS | C32: Ordóñez Alarcón Wilson Gabriel | D32: 35009 | E32: =IF(MONTH(D32)=$C$3,"SI","NO") -> NO | F32: 45855 | G32: =IF(AND(YEAR($B$3)-YEAR(F32)>0,MONTH(F32)=$C$3),"SI","NO") -> NO | H32: ECUADOR | I32: USD | J32: 2000 | K32: BANCO DEL PICHINCHA - AHO | L32: 2205792931
A33: BEE Consultoria y Negocios | B33: INDEFINIDO | C33: Pacheco Meza Jennifer | D33: 34656 | E33: =IF(MONTH(D33)=$C$3,"SI","NO") -> NO | F33: 45537 | G33: =IF(AND(YEAR($B$3)-YEAR(F33)>0,MONTH(F33)=$C$3),"SI","NO") -> NO | H33: Colombia | I33: COP | J33: 6552000 | K33: BANCOLOMBIA - AHO | L33: 51666250714
A34: BEE Consultoria y Negocios | B34: PRESTACION DE SERVICIOS | C34: Peña Hernández Weimar | D34: 33240 | E34: =IF(MONTH(D34)=$C$3,"SI","NO") -> NO | F34: 45120 | G34: =IF(AND(YEAR($B$3)-YEAR(F34)>0,MONTH(F34)=$C$3),"SI","NO") -> NO | H34: Colombia | I34: COP | J34: 15000000 | K34: LULO BANK - AHO | L34: 507721738059
A35: BEE Consultoria y Negocios | B35: PRESTACION DE SERVICIOS | C35: Quezada Sanmartín Nixon Douglas | D35: 35332 | E35: =IF(MONTH(D35)=$C$3,"SI","NO") -> NO | F35: 45854 | G35: =IF(AND(YEAR($B$3)-YEAR(F35)>0,MONTH(F35)=$C$3),"SI","NO") -> NO | H35: ECUADOR | I35: USD | J35: 2000 | K35: BANCO DEL PICHINCHA - AHO | L35: 2207506148
A36: BEE Consultoria y Negocios | B36: PRESTACION DE SERVICIOS | C36: Ramírez Albarracín Andrés David | D36: 36998 | E36: =IF(MONTH(D36)=$C$3,"SI","NO") -> NO | F36: 46121 | G36: =IF(AND(YEAR($B$3)-YEAR(F36)>0,MONTH(F36)=$C$3),"SI","NO") -> NO | H36: Colombia | I36: COP | J36: 9600000 | K36: BANCOLOMBIA - AHO | L36: 25868648590
A37: BEE Consultoria y Negocios | B37: INDEFINIDO | C37: Rodríguez Merchan Darwin Alexander | D37: 36135 | E37: =IF(MONTH(D37)=$C$3,"SI","NO") -> NO | F37: 45597 | G37: =IF(AND(YEAR($B$3)-YEAR(F37)>0,MONTH(F37)=$C$3),"SI","NO") -> NO | H37: ECUADOR | I37: USD | J37: 2080 | K37: BANCO DEL PICHINCHA - AHO | L37: 2208420372
A38: BEE Consultoria y Negocios | B38: PRESTACION DE SERVICIOS | C38: Rosero Velasco Maritza Nataly | D38: 33486 | E38: =IF(MONTH(D38)=$C$3,"SI","NO") -> NO | F38: 46072 | G38: =IF(AND(YEAR($B$3)-YEAR(F38)>0,MONTH(F38)=$C$3),"SI","NO") -> NO | H38: ECUADOR | I38: USD | J38: 1900 | K38: BANCO DEL PICHINCHA - AHO | L38: 2200974152
A39: BEE Consultoria y Negocios | B39: PRESTACION DE SERVICIOS | C39: Salazar Ruíz Xavier Ulises | D39: 22862 | E39: =IF(MONTH(D39)=$C$3,"SI","NO") -> NO | F39: 45875 | G39: =IF(AND(YEAR($B$3)-YEAR(F39)>0,MONTH(F39)=$C$3),"SI","NO") -> NO | H39: ECUADOR | I39: USD | J39: 3900 | K39: BANCO DE GUAYAQUIL - AHO | L39: 9699665
A40: BEE Consultoria y Negocios | B40: PRESTACION DE SERVICIOS | C40: Simbaña Cusicagua Kevin Dario | D40: 34956 | E40: =IF(MONTH(D40)=$C$3,"SI","NO") -> NO | F40: 45854 | G40: =IF(AND(YEAR($B$3)-YEAR(F40)>0,MONTH(F40)=$C$3),"SI","NO") -> NO | H40: ECUADOR | I40: USD | J40: 2000 | K40: BANCO DEL PICHINCHA - AHO | L40: 2207253794
A41: BEE Consultoria y Negocios | B41: PRESTACION DE SERVICIOS | C41: Velásquez González David José | D41: 30559 | E41: =IF(MONTH(D41)=$C$3,"SI","NO") -> NO | F41: 46125 | G41: =IF(AND(YEAR($B$3)-YEAR(F41)>0,MONTH(F41)=$C$3),"SI","NO") -> NO | H41: Colombia | I41: COP | J41: 13000000 | K41: BANCOLOMBIA - AHO | L41: 48706021125
...

Sheet REPORTE NOVEDADES
B1: 46082 | C1: Dias CALENDARIO Mes | D1: 31
A3: SEC | B3: NOMBRE DEL COLABORADOR | C3: ='TALENTOS BEE'!B6 -> TIPO CONTRATO | D3: PAÍS UBICACIÓN | E3: FECHA DE NACIMIENTO | F3: BONO CUMPLEAÑOS | G3: FECHA INGRESO A LA COMPAÑÍA | H3: INCREMENTO SALARIAL | I3: HORAS EXTRAS | J3: DESCRIPCION NOVEDAD
A4: 1 | B4: Weimar Peña Hernández | C4: INDEFINIDO | D4: Ecuador | E4: ='TALENTOS BEE'!D7 -> 31207 | F4: NO | G4: ='TALENTOS BEE'!F7 -> 44599 | H4: NO | J4: Descuento por $497.53.
A5: 4 | B5: Víctor Daniel Perez Díaz | C5: INDEFINIDO | D5: Ecuador | E5: ='TALENTOS BEE'!D10 -> 32845 | F5: NO | G5: ='TALENTOS BEE'!F10 -> 44995 | H5: NO | J5: Descuento de $537.27 acordado con el proveedor
A6: 6 | B6: Anyela Julieth Castillo Amezquita | C6: PRESTACIÓN DE SERVICIOS | D6: Colombia | E6: ='TALENTOS BEE'!D12 -> 35246 | F6: NO | G6: ='TALENTOS BEE'!F12 -> 46125 | H6: NO | J6: Descuento por $26.64
A7: 7 | B7: Darwin Alexander Rodríguez Merchan | C7: INDEFINIDO | D7: Colombia | E7: ='TALENTOS BEE'!D13 -> 35671 | F7: NO | G7: ='TALENTOS BEE'!F13 -> 46076 | H7: NO | J7: Descuento por $220.82 acordado con el proveedor
A8: 8 | B8: Johana Estefanía Nicolalde Perugachi | C8: INDEFINIDO | D8: Colombia | E8: ='TALENTOS BEE'!D14 -> 34229 | F8: NO | G8: ='TALENTOS BEE'!F14 -> 45597 | H8: NO | J8: Descuento de $220.82 acordado con el proveedor
A9: 11 | B9: Kevin Caicedo Álvarez | C9: INDEFINIDO | D9: Colombia | E9: ='TALENTOS BEE'!D17 -> 34352 | F9: NO | G9: ='TALENTOS BEE'!F17 -> 45855 | H9: NO | J9: -2-feb-26: se acuerda con proveedor la facturación del 50% de la tarifa para el mes de febrero 2026.
A10: 12 | B10: Daniela Castro González | C10: INDEFINIDO | D10: Colombia | E10: ='TALENTOS BEE'!D18 -> 36753 | F10: NO | G10: ='TALENTOS BEE'!F18 -> 46079 | H10: NO
A11: 13 | B11: Johnatan Alexander Mena Salcedo | C11: PRESTACIÓN DE SERVICIOS | D11: Ecuador | E11: ='TALENTOS BEE'!D19 -> 33927 | F11: NO | G11: ='TALENTOS BEE'!F19 -> 45880 | H11: NO | J11: Descuento de $220.82 acordado con el proveedor
A12: 14 | B12: Maritza Nataly Rosero Velasco | C12: PRESTACIÓN DE SERVICIOS | D12: Ecuador | E12: ='TALENTOS BEE'!D20 -> 26847 | F12: NO | G12: ='TALENTOS BEE'!F20 -> 45839 | H12: NO | J12: Ingresó el 19 de febrero de 2026
A13: 15 | B13: Nicole Yadira Chavez Garcia | C13: PRESTACIÓN DE SERVICIOS | D13: Ecuador | E13: ='TALENTOS BEE'!D21 -> 33778 | F13: NO | G13: ='TALENTOS BEE'!F21 -> 46121 | H13: NO | J13: Ingresó el 23 de febrero de 2026
A14: 17 | B14: Pratt Christian Garcia Regalado | C14: PRESTACIÓN DE SERVICIOS | D14: Ecuador | E14: ='TALENTOS BEE'!D23 -> 35964 | F14: NO | G14: ='TALENTOS BEE'!F23 -> 45835 | H14: NO | J14: Ingresó el 26 de febrero de 2026
A15: 18
A16: 19
A17: 20
A18: 21
A19: 23
A20: 24
A21: 25
A22: 26
A23: 28
A24: 29
A25: 30
A26: 31
... A32: 39
